[2023-05-11T17:44:57.809+0000] {warnings.py:110} WARNING - /usr/local/lib/python3.7/site-packages/***/models/taskinstance.py:871: SAWarning: TypeDecorator ExecutorConfigType() will not produce a cache key because the ``cache_ok`` attribute is not set to True.  This can have significant performance implications including some performance degradations in comparison to prior SQLAlchemy versions.  Set this attribute to True if this type object's state is safe to use in a cache key, or False to disable this warning. (Background on this error at: https://sqlalche.me/e/14/cprf)
  ti: TaskInstance | None = qry.with_for_update().one_or_none()

[2023-05-11T17:44:57.905+0000] {taskinstance.py:1165} INFO - Dependencies all met for <TaskInstance: job_1_tranvietcuong.file_process scheduled__2023-05-11T17:05:00+00:00 [queued]>
[2023-05-11T17:44:57.962+0000] {taskinstance.py:1165} INFO - Dependencies all met for <TaskInstance: job_1_tranvietcuong.file_process scheduled__2023-05-11T17:05:00+00:00 [queued]>
[2023-05-11T17:44:57.964+0000] {taskinstance.py:1362} INFO - 
--------------------------------------------------------------------------------
[2023-05-11T17:44:57.966+0000] {taskinstance.py:1363} INFO - Starting attempt 1 of 2
[2023-05-11T17:44:57.968+0000] {taskinstance.py:1364} INFO - 
--------------------------------------------------------------------------------
[2023-05-11T17:44:58.048+0000] {taskinstance.py:1383} INFO - Executing <Task(PythonOperator): file_process> on 2023-05-11 17:05:00+00:00
[2023-05-11T17:44:58.065+0000] {standard_task_runner.py:54} INFO - Started process 326 to run task
[2023-05-11T17:44:58.078+0000] {standard_task_runner.py:82} INFO - Running: ['***', 'tasks', 'run', 'job_1_tranvietcuong', 'file_process', 'scheduled__2023-05-11T17:05:00+00:00', '--job-id', '155', '--raw', '--subdir', 'DAGS_FOLDER/tranvietcuong.py', '--cfg-path', '/tmp/tmpbma8_lvq']
[2023-05-11T17:44:58.080+0000] {standard_task_runner.py:83} INFO - Job 155: Subtask file_process
[2023-05-11T17:44:58.085+0000] {dagbag.py:525} INFO - Filling up the DagBag from /opt/***/dags/tranvietcuong.py
[2023-05-11T17:44:58.424+0000] {task_command.py:384} INFO - Running <TaskInstance: job_1_tranvietcuong.file_process scheduled__2023-05-11T17:05:00+00:00 [running]> on host 09877495cfa0
[2023-05-11T17:44:58.438+0000] {warnings.py:110} WARNING - /usr/local/lib/python3.7/site-packages/***/models/taskinstance.py:873: SAWarning: TypeDecorator ExecutorConfigType() will not produce a cache key because the ``cache_ok`` attribute is not set to True.  This can have significant performance implications including some performance degradations in comparison to prior SQLAlchemy versions.  Set this attribute to True if this type object's state is safe to use in a cache key, or False to disable this warning. (Background on this error at: https://sqlalche.me/e/14/cprf)
  ti = qry.one_or_none()

[2023-05-11T17:44:58.950+0000] {taskinstance.py:1592} INFO - Exporting the following env vars:
AIRFLOW_CTX_DAG_OWNER=***
AIRFLOW_CTX_DAG_ID=job_1_tranvietcuong
AIRFLOW_CTX_TASK_ID=file_process
AIRFLOW_CTX_EXECUTION_DATE=2023-05-11T17:05:00+00:00
AIRFLOW_CTX_TRY_NUMBER=1
AIRFLOW_CTX_DAG_RUN_ID=scheduled__2023-05-11T17:05:00+00:00
[2023-05-11T17:44:58.957+0000] {taskinstance.py:1851} ERROR - Task failed with exception
Traceback (most recent call last):
  File "/usr/local/lib/python3.7/site-packages/airflow/operators/python.py", line 175, in execute
    return_value = self.execute_callable()
  File "/usr/local/lib/python3.7/site-packages/airflow/operators/python.py", line 193, in execute_callable
    return self.python_callable(*self.op_args, **self.op_kwargs)
  File "/opt/airflow/dags/tranvietcuong.py", line 15, in file_process
    with open('/tmp/' + file_read, 'r') as f:
IsADirectoryError: [Errno 21] Is a directory: '/tmp/'
[2023-05-11T17:44:58.986+0000] {warnings.py:110} WARNING - /usr/local/lib/python3.7/site-packages/***/models/taskinstance.py:873: SAWarning: TypeDecorator ExecutorConfigType() will not produce a cache key because the ``cache_ok`` attribute is not set to True.  This can have significant performance implications including some performance degradations in comparison to prior SQLAlchemy versions.  Set this attribute to True if this type object's state is safe to use in a cache key, or False to disable this warning. (Background on this error at: https://sqlalche.me/e/14/cprf)
  ti = qry.one_or_none()

[2023-05-11T17:44:59.050+0000] {taskinstance.py:1406} INFO - Marking task as UP_FOR_RETRY. dag_id=job_1_tranvietcuong, task_id=file_process, execution_date=20230511T170500, start_date=20230511T174457, end_date=20230511T174459
[2023-05-11T17:44:59.255+0000] {standard_task_runner.py:107} ERROR - Failed to execute job 155 for task file_process ([Errno 21] Is a directory: '/tmp/'; 326)
[2023-05-11T17:44:59.345+0000] {local_task_job.py:164} INFO - Task exited with return code 1
[2023-05-11T17:44:59.954+0000] {local_task_job.py:273} INFO - 0 downstream tasks scheduled from follow-on schedule check
