[2023-05-11T17:41:07.409+0000] {warnings.py:110} WARNING - /usr/local/lib/python3.7/site-packages/***/models/taskinstance.py:871: SAWarning: TypeDecorator ExecutorConfigType() will not produce a cache key because the ``cache_ok`` attribute is not set to True.  This can have significant performance implications including some performance degradations in comparison to prior SQLAlchemy versions.  Set this attribute to True if this type object's state is safe to use in a cache key, or False to disable this warning. (Background on this error at: https://sqlalche.me/e/14/cprf)
  ti: TaskInstance | None = qry.with_for_update().one_or_none()

[2023-05-11T17:41:07.458+0000] {taskinstance.py:1165} INFO - Dependencies all met for <TaskInstance: spark_process_data_14.spark_job_clean_data_by_ssh scheduled__2023-05-10T17:00:00+00:00 [queued]>
[2023-05-11T17:41:07.495+0000] {taskinstance.py:1165} INFO - Dependencies all met for <TaskInstance: spark_process_data_14.spark_job_clean_data_by_ssh scheduled__2023-05-10T17:00:00+00:00 [queued]>
[2023-05-11T17:41:07.496+0000] {taskinstance.py:1362} INFO - 
--------------------------------------------------------------------------------
[2023-05-11T17:41:07.496+0000] {taskinstance.py:1363} INFO - Starting attempt 2 of 2
[2023-05-11T17:41:07.497+0000] {taskinstance.py:1364} INFO - 
--------------------------------------------------------------------------------
[2023-05-11T17:41:07.563+0000] {taskinstance.py:1383} INFO - Executing <Task(SSHOperator): spark_job_clean_data_by_ssh> on 2023-05-10 17:00:00+00:00
[2023-05-11T17:41:07.578+0000] {standard_task_runner.py:54} INFO - Started process 129 to run task
[2023-05-11T17:41:07.591+0000] {standard_task_runner.py:82} INFO - Running: ['***', 'tasks', 'run', 'spark_process_data_14', 'spark_job_clean_data_by_ssh', 'scheduled__2023-05-10T17:00:00+00:00', '--job-id', '126', '--raw', '--subdir', 'DAGS_FOLDER/spark_process_scheduler.py', '--cfg-path', '/tmp/tmp98gs8rt7']
[2023-05-11T17:41:07.593+0000] {standard_task_runner.py:83} INFO - Job 126: Subtask spark_job_clean_data_by_ssh
[2023-05-11T17:41:07.597+0000] {dagbag.py:525} INFO - Filling up the DagBag from /opt/***/dags/spark_process_scheduler.py
[2023-05-11T17:41:08.107+0000] {task_command.py:384} INFO - Running <TaskInstance: spark_process_data_14.spark_job_clean_data_by_ssh scheduled__2023-05-10T17:00:00+00:00 [running]> on host 09877495cfa0
[2023-05-11T17:41:08.133+0000] {warnings.py:110} WARNING - /usr/local/lib/python3.7/site-packages/***/models/taskinstance.py:873: SAWarning: TypeDecorator ExecutorConfigType() will not produce a cache key because the ``cache_ok`` attribute is not set to True.  This can have significant performance implications including some performance degradations in comparison to prior SQLAlchemy versions.  Set this attribute to True if this type object's state is safe to use in a cache key, or False to disable this warning. (Background on this error at: https://sqlalche.me/e/14/cprf)
  ti = qry.one_or_none()

[2023-05-11T17:41:08.637+0000] {taskinstance.py:1592} INFO - Exporting the following env vars:
AIRFLOW_CTX_DAG_EMAIL=pioneer22022001@gmail.com
AIRFLOW_CTX_DAG_OWNER=***
AIRFLOW_CTX_DAG_ID=spark_process_data_14
AIRFLOW_CTX_TASK_ID=spark_job_clean_data_by_ssh
AIRFLOW_CTX_EXECUTION_DATE=2023-05-10T17:00:00+00:00
AIRFLOW_CTX_TRY_NUMBER=2
AIRFLOW_CTX_DAG_RUN_ID=scheduled__2023-05-10T17:00:00+00:00
[2023-05-11T17:41:08.639+0000] {ssh.py:135} INFO - Creating ssh_client
[2023-05-11T17:41:08.796+0000] {ssh.py:112} INFO - ssh_hook is not provided or invalid. Trying ssh_conn_id to create SSHHook.
[2023-05-11T17:41:08.857+0000] {base.py:71} INFO - Using connection ID 'ssh_connection_spark' for task execution.
[2023-05-11T17:41:08.859+0000] {ssh.py:299} WARNING - No Host Key Verification. This won't protect against Man-In-The-Middle attacks
[2023-05-11T17:41:11.913+0000] {ssh.py:341} INFO - Failed to connect. Sleeping before retry attempt 1
[2023-05-11T17:41:12.674+0000] {warnings.py:110} WARNING - /usr/local/lib/python3.7/site-packages/***/models/taskinstance.py:873: SAWarning: TypeDecorator ExecutorConfigType() will not produce a cache key because the ``cache_ok`` attribute is not set to True.  This can have significant performance implications including some performance degradations in comparison to prior SQLAlchemy versions.  Set this attribute to True if this type object's state is safe to use in a cache key, or False to disable this warning. (Background on this error at: https://sqlalche.me/e/14/cprf)
  ti = qry.one_or_none()

[2023-05-11T17:41:19.913+0000] {ssh.py:341} INFO - Failed to connect. Sleeping before retry attempt 2
[2023-05-11T17:41:27.241+0000] {taskinstance.py:1851} ERROR - Task failed with exception
Traceback (most recent call last):
  File "/usr/local/lib/python3.7/site-packages/airflow/providers/ssh/operators/ssh.py", line 172, in execute
    with self.get_ssh_client() as ssh_client:
  File "/usr/local/lib/python3.7/site-packages/airflow/providers/ssh/operators/ssh.py", line 136, in get_ssh_client
    return self.get_hook().get_conn()
  File "/usr/local/lib/python3.7/site-packages/airflow/providers/ssh/hooks/ssh.py", line 348, in get_conn
    before_sleep=log_before_sleep,
  File "/usr/local/lib/python3.7/site-packages/tenacity/__init__.py", line 347, in __iter__
    do = self.iter(retry_state=retry_state)
  File "/usr/local/lib/python3.7/site-packages/tenacity/__init__.py", line 325, in iter
    raise retry_exc.reraise()
  File "/usr/local/lib/python3.7/site-packages/tenacity/__init__.py", line 158, in reraise
    raise self.last_attempt.result()
  File "/usr/local/lib/python3.7/concurrent/futures/_base.py", line 428, in result
    return self.__get_result()
  File "/usr/local/lib/python3.7/concurrent/futures/_base.py", line 384, in __get_result
    raise self._exception
  File "/usr/local/lib/python3.7/site-packages/airflow/providers/ssh/hooks/ssh.py", line 351, in get_conn
    client.connect(**connect_kwargs)
  File "/usr/local/lib/python3.7/site-packages/paramiko/client.py", line 388, in connect
    raise NoValidConnectionsError(errors)
paramiko.ssh_exception.NoValidConnectionsError: [Errno None] Unable to connect to port 22 on 172.27.0.9
[2023-05-11T17:41:27.267+0000] {warnings.py:110} WARNING - /usr/local/lib/python3.7/site-packages/***/models/taskinstance.py:873: SAWarning: TypeDecorator ExecutorConfigType() will not produce a cache key because the ``cache_ok`` attribute is not set to True.  This can have significant performance implications including some performance degradations in comparison to prior SQLAlchemy versions.  Set this attribute to True if this type object's state is safe to use in a cache key, or False to disable this warning. (Background on this error at: https://sqlalche.me/e/14/cprf)
  ti = qry.one_or_none()

[2023-05-11T17:41:27.290+0000] {taskinstance.py:1406} INFO - Marking task as FAILED. dag_id=spark_process_data_14, task_id=spark_job_clean_data_by_ssh, execution_date=20230510T170000, start_date=20230511T174107, end_date=20230511T174127
[2023-05-11T17:41:27.352+0000] {warnings.py:110} WARNING - /usr/local/lib/python3.7/site-packages/***/utils/email.py:120: RemovedInAirflow3Warning: Fetching SMTP credentials from configuration variables will be deprecated in a future release. Please set credentials using a connection instead.
  send_mime_email(e_from=mail_from, e_to=recipients, mime_msg=msg, conn_id=conn_id, dryrun=dryrun)

[2023-05-11T17:41:27.352+0000] {configuration.py:569} WARNING - section/key [smtp/smtp_user] not found in config
[2023-05-11T17:41:27.353+0000] {email.py:229} INFO - Email alerting: attempt 1
[2023-05-11T17:41:27.379+0000] {configuration.py:569} WARNING - section/key [smtp/smtp_user] not found in config
[2023-05-11T17:41:27.379+0000] {email.py:229} INFO - Email alerting: attempt 1
[2023-05-11T17:41:27.381+0000] {taskinstance.py:1914} ERROR - Failed to send email to: ['pioneer22022001@gmail.com']
Traceback (most recent call last):
  File "/usr/local/lib/python3.7/site-packages/airflow/models/taskinstance.py", line 1457, in _run_raw_task
    self._execute_task_with_callbacks(context, test_mode)
  File "/usr/local/lib/python3.7/site-packages/airflow/models/taskinstance.py", line 1603, in _execute_task_with_callbacks
    result = self._execute_task(context, task_orig)
  File "/usr/local/lib/python3.7/site-packages/airflow/models/taskinstance.py", line 1664, in _execute_task
    result = execute_callable(context=context)
  File "/usr/local/lib/python3.7/site-packages/airflow/providers/ssh/operators/ssh.py", line 172, in execute
    with self.get_ssh_client() as ssh_client:
  File "/usr/local/lib/python3.7/site-packages/airflow/providers/ssh/operators/ssh.py", line 136, in get_ssh_client
    return self.get_hook().get_conn()
  File "/usr/local/lib/python3.7/site-packages/airflow/providers/ssh/hooks/ssh.py", line 348, in get_conn
    before_sleep=log_before_sleep,
  File "/usr/local/lib/python3.7/site-packages/tenacity/__init__.py", line 347, in __iter__
    do = self.iter(retry_state=retry_state)
  File "/usr/local/lib/python3.7/site-packages/tenacity/__init__.py", line 325, in iter
    raise retry_exc.reraise()
  File "/usr/local/lib/python3.7/site-packages/tenacity/__init__.py", line 158, in reraise
    raise self.last_attempt.result()
  File "/usr/local/lib/python3.7/concurrent/futures/_base.py", line 428, in result
    return self.__get_result()
  File "/usr/local/lib/python3.7/concurrent/futures/_base.py", line 384, in __get_result
    raise self._exception
  File "/usr/local/lib/python3.7/site-packages/airflow/providers/ssh/hooks/ssh.py", line 351, in get_conn
    client.connect(**connect_kwargs)
  File "/usr/local/lib/python3.7/site-packages/paramiko/client.py", line 388, in connect
    raise NoValidConnectionsError(errors)
paramiko.ssh_exception.NoValidConnectionsError: [Errno None] Unable to connect to port 22 on 172.27.0.9

During handling of the above exception, another exception occurred:

Traceback (most recent call last):
  File "/usr/local/lib/python3.7/site-packages/airflow/models/taskinstance.py", line 2311, in email_alert
    send_email(task.email, subject, html_content)
  File "/usr/local/lib/python3.7/site-packages/airflow/utils/email.py", line 72, in send_email
    **kwargs,
  File "/usr/local/lib/python3.7/site-packages/airflow/utils/email.py", line 120, in send_email_smtp
    send_mime_email(e_from=mail_from, e_to=recipients, mime_msg=msg, conn_id=conn_id, dryrun=dryrun)
  File "/usr/local/lib/python3.7/site-packages/airflow/utils/email.py", line 231, in send_mime_email
    smtp_conn = _get_smtp_connection(smtp_host, smtp_port, smtp_timeout, smtp_ssl)
  File "/usr/local/lib/python3.7/site-packages/airflow/utils/email.py", line 265, in _get_smtp_connection
    else smtplib.SMTP(host=host, port=port, timeout=timeout)
  File "/usr/local/lib/python3.7/smtplib.py", line 251, in __init__
    (code, msg) = self.connect(host, port)
  File "/usr/local/lib/python3.7/smtplib.py", line 336, in connect
    self.sock = self._get_socket(host, port, self.timeout)
  File "/usr/local/lib/python3.7/smtplib.py", line 307, in _get_socket
    self.source_address)
  File "/usr/local/lib/python3.7/socket.py", line 728, in create_connection
    raise err
  File "/usr/local/lib/python3.7/socket.py", line 716, in create_connection
    sock.connect(sa)
OSError: [Errno 99] Cannot assign requested address

During handling of the above exception, another exception occurred:

Traceback (most recent call last):
  File "/usr/local/lib/python3.7/site-packages/airflow/models/taskinstance.py", line 1912, in handle_failure
    self.email_alert(error, task)
  File "/usr/local/lib/python3.7/site-packages/airflow/models/taskinstance.py", line 2313, in email_alert
    send_email(task.email, subject, html_content_err)
  File "/usr/local/lib/python3.7/site-packages/airflow/utils/email.py", line 72, in send_email
    **kwargs,
  File "/usr/local/lib/python3.7/site-packages/airflow/utils/email.py", line 120, in send_email_smtp
    send_mime_email(e_from=mail_from, e_to=recipients, mime_msg=msg, conn_id=conn_id, dryrun=dryrun)
  File "/usr/local/lib/python3.7/site-packages/airflow/utils/email.py", line 231, in send_mime_email
    smtp_conn = _get_smtp_connection(smtp_host, smtp_port, smtp_timeout, smtp_ssl)
  File "/usr/local/lib/python3.7/site-packages/airflow/utils/email.py", line 265, in _get_smtp_connection
    else smtplib.SMTP(host=host, port=port, timeout=timeout)
  File "/usr/local/lib/python3.7/smtplib.py", line 251, in __init__
    (code, msg) = self.connect(host, port)
  File "/usr/local/lib/python3.7/smtplib.py", line 336, in connect
    self.sock = self._get_socket(host, port, self.timeout)
  File "/usr/local/lib/python3.7/smtplib.py", line 307, in _get_socket
    self.source_address)
  File "/usr/local/lib/python3.7/socket.py", line 728, in create_connection
    raise err
  File "/usr/local/lib/python3.7/socket.py", line 716, in create_connection
    sock.connect(sa)
OSError: [Errno 99] Cannot assign requested address
[2023-05-11T17:41:27.422+0000] {standard_task_runner.py:107} ERROR - Failed to execute job 126 for task spark_job_clean_data_by_ssh ([Errno None] Unable to connect to port 22 on 172.27.0.9; 129)
[2023-05-11T17:41:27.463+0000] {local_task_job.py:164} INFO - Task exited with return code 1
[2023-05-11T17:41:27.544+0000] {local_task_job.py:273} INFO - 0 downstream tasks scheduled from follow-on schedule check
