[2023-05-17T09:00:46.331+0000] {warnings.py:110} WARNING - /usr/local/lib/python3.7/site-packages/***/models/taskinstance.py:871: SAWarning: TypeDecorator ExecutorConfigType() will not produce a cache key because the ``cache_ok`` attribute is not set to True.  This can have significant performance implications including some performance degradations in comparison to prior SQLAlchemy versions.  Set this attribute to True if this type object's state is safe to use in a cache key, or False to disable this warning. (Background on this error at: https://sqlalche.me/e/14/cprf)
  ti: TaskInstance | None = qry.with_for_update().one_or_none()

[2023-05-17T09:00:46.409+0000] {taskinstance.py:1165} INFO - Dependencies all met for <TaskInstance: job_1_tranvietcuong_2.file_sensor scheduled__2023-05-11T17:50:00+00:00 [queued]>
[2023-05-17T09:00:46.462+0000] {taskinstance.py:1165} INFO - Dependencies all met for <TaskInstance: job_1_tranvietcuong_2.file_sensor scheduled__2023-05-11T17:50:00+00:00 [queued]>
[2023-05-17T09:00:46.463+0000] {taskinstance.py:1362} INFO - 
--------------------------------------------------------------------------------
[2023-05-17T09:00:46.465+0000] {taskinstance.py:1363} INFO - Starting attempt 1 of 1
[2023-05-17T09:00:46.465+0000] {taskinstance.py:1364} INFO - 
--------------------------------------------------------------------------------
[2023-05-17T09:00:46.557+0000] {taskinstance.py:1383} INFO - Executing <Task(FileSensor): file_sensor> on 2023-05-11 17:50:00+00:00
[2023-05-17T09:00:46.575+0000] {standard_task_runner.py:54} INFO - Started process 249 to run task
[2023-05-17T09:00:46.596+0000] {standard_task_runner.py:82} INFO - Running: ['***', 'tasks', 'run', 'job_1_tranvietcuong_2', 'file_sensor', 'scheduled__2023-05-11T17:50:00+00:00', '--job-id', '3903', '--raw', '--subdir', 'DAGS_FOLDER/tranvietcuong.py', '--cfg-path', '/tmp/tmp4cwrk8m7']
[2023-05-17T09:00:46.600+0000] {standard_task_runner.py:83} INFO - Job 3903: Subtask file_sensor
[2023-05-17T09:00:46.605+0000] {dagbag.py:525} INFO - Filling up the DagBag from /opt/***/dags/tranvietcuong.py
[2023-05-17T09:00:46.956+0000] {task_command.py:384} INFO - Running <TaskInstance: job_1_tranvietcuong_2.file_sensor scheduled__2023-05-11T17:50:00+00:00 [running]> on host b5c083b5be9a
[2023-05-17T09:00:46.970+0000] {warnings.py:110} WARNING - /usr/local/lib/python3.7/site-packages/***/models/taskinstance.py:873: SAWarning: TypeDecorator ExecutorConfigType() will not produce a cache key because the ``cache_ok`` attribute is not set to True.  This can have significant performance implications including some performance degradations in comparison to prior SQLAlchemy versions.  Set this attribute to True if this type object's state is safe to use in a cache key, or False to disable this warning. (Background on this error at: https://sqlalche.me/e/14/cprf)
  ti = qry.one_or_none()

[2023-05-17T09:00:47.386+0000] {taskinstance.py:1592} INFO - Exporting the following env vars:
AIRFLOW_CTX_DAG_EMAIL=user@example.com
AIRFLOW_CTX_DAG_OWNER=***
AIRFLOW_CTX_DAG_ID=job_1_tranvietcuong_2
AIRFLOW_CTX_TASK_ID=file_sensor
AIRFLOW_CTX_EXECUTION_DATE=2023-05-11T17:50:00+00:00
AIRFLOW_CTX_TRY_NUMBER=1
AIRFLOW_CTX_DAG_RUN_ID=scheduled__2023-05-11T17:50:00+00:00
[2023-05-17T09:00:47.498+0000] {base.py:71} INFO - Using connection ID 'fs_default' for task execution.
[2023-05-17T09:00:47.501+0000] {filesystem.py:58} INFO - Poking for file /opt/***/dags/tmp/*dejob*
[2023-05-17T09:00:47.531+0000] {warnings.py:110} WARNING - /usr/local/lib/python3.7/site-packages/***/models/taskinstance.py:873: SAWarning: TypeDecorator ExecutorConfigType() will not produce a cache key because the ``cache_ok`` attribute is not set to True.  This can have significant performance implications including some performance degradations in comparison to prior SQLAlchemy versions.  Set this attribute to True if this type object's state is safe to use in a cache key, or False to disable this warning. (Background on this error at: https://sqlalche.me/e/14/cprf)
  ti = qry.one_or_none()

[2023-05-17T09:00:47.827+0000] {taskinstance.py:1815} INFO - Rescheduling task, marking task as UP_FOR_RESCHEDULE
[2023-05-17T09:00:47.871+0000] {local_task_job.py:164} INFO - Task exited with return code 0
[2023-05-17T09:00:48.078+0000] {local_task_job.py:273} INFO - 0 downstream tasks scheduled from follow-on schedule check
[2023-05-17T09:01:05.395+0000] {warnings.py:110} WARNING - /usr/local/lib/python3.7/site-packages/***/models/taskinstance.py:871: SAWarning: TypeDecorator ExecutorConfigType() will not produce a cache key because the ``cache_ok`` attribute is not set to True.  This can have significant performance implications including some performance degradations in comparison to prior SQLAlchemy versions.  Set this attribute to True if this type object's state is safe to use in a cache key, or False to disable this warning. (Background on this error at: https://sqlalche.me/e/14/cprf)
  ti: TaskInstance | None = qry.with_for_update().one_or_none()

[2023-05-17T09:01:05.475+0000] {taskinstance.py:1165} INFO - Dependencies all met for <TaskInstance: job_1_tranvietcuong_2.file_sensor scheduled__2023-05-11T17:50:00+00:00 [queued]>
[2023-05-17T09:01:05.540+0000] {taskinstance.py:1165} INFO - Dependencies all met for <TaskInstance: job_1_tranvietcuong_2.file_sensor scheduled__2023-05-11T17:50:00+00:00 [queued]>
[2023-05-17T09:01:05.542+0000] {taskinstance.py:1362} INFO - 
--------------------------------------------------------------------------------
[2023-05-17T09:01:05.544+0000] {taskinstance.py:1363} INFO - Starting attempt 1 of 1
[2023-05-17T09:01:05.546+0000] {taskinstance.py:1364} INFO - 
--------------------------------------------------------------------------------
[2023-05-17T09:01:05.673+0000] {taskinstance.py:1383} INFO - Executing <Task(FileSensor): file_sensor> on 2023-05-11 17:50:00+00:00
[2023-05-17T09:01:05.692+0000] {standard_task_runner.py:54} INFO - Started process 288 to run task
[2023-05-17T09:01:05.708+0000] {standard_task_runner.py:82} INFO - Running: ['***', 'tasks', 'run', 'job_1_tranvietcuong_2', 'file_sensor', 'scheduled__2023-05-11T17:50:00+00:00', '--job-id', '3917', '--raw', '--subdir', 'DAGS_FOLDER/tranvietcuong.py', '--cfg-path', '/tmp/tmpg0l45tln']
[2023-05-17T09:01:05.711+0000] {standard_task_runner.py:83} INFO - Job 3917: Subtask file_sensor
[2023-05-17T09:01:05.715+0000] {dagbag.py:525} INFO - Filling up the DagBag from /opt/***/dags/tranvietcuong.py
[2023-05-17T09:01:06.092+0000] {task_command.py:384} INFO - Running <TaskInstance: job_1_tranvietcuong_2.file_sensor scheduled__2023-05-11T17:50:00+00:00 [running]> on host b5c083b5be9a
[2023-05-17T09:01:06.107+0000] {warnings.py:110} WARNING - /usr/local/lib/python3.7/site-packages/***/models/taskinstance.py:873: SAWarning: TypeDecorator ExecutorConfigType() will not produce a cache key because the ``cache_ok`` attribute is not set to True.  This can have significant performance implications including some performance degradations in comparison to prior SQLAlchemy versions.  Set this attribute to True if this type object's state is safe to use in a cache key, or False to disable this warning. (Background on this error at: https://sqlalche.me/e/14/cprf)
  ti = qry.one_or_none()

[2023-05-17T09:01:06.706+0000] {taskinstance.py:1592} INFO - Exporting the following env vars:
AIRFLOW_CTX_DAG_EMAIL=user@example.com
AIRFLOW_CTX_DAG_OWNER=***
AIRFLOW_CTX_DAG_ID=job_1_tranvietcuong_2
AIRFLOW_CTX_TASK_ID=file_sensor
AIRFLOW_CTX_EXECUTION_DATE=2023-05-11T17:50:00+00:00
AIRFLOW_CTX_TRY_NUMBER=1
AIRFLOW_CTX_DAG_RUN_ID=scheduled__2023-05-11T17:50:00+00:00
[2023-05-17T09:01:06.820+0000] {base.py:71} INFO - Using connection ID 'fs_default' for task execution.
[2023-05-17T09:01:06.822+0000] {filesystem.py:58} INFO - Poking for file /opt/***/dags/tmp/*dejob*
[2023-05-17T09:01:06.826+0000] {taskinstance.py:1851} ERROR - Task failed with exception
Traceback (most recent call last):
  File "/usr/local/lib/python3.7/site-packages/airflow/sensors/base.py", line 200, in execute
    raise AirflowSensorTimeout(f"Snap. Time is OUT. DAG id: {log_dag_id}")
airflow.exceptions.AirflowSensorTimeout: Snap. Time is OUT. DAG id: job_1_tranvietcuong_2
[2023-05-17T09:01:06.852+0000] {warnings.py:110} WARNING - /usr/local/lib/python3.7/site-packages/***/models/taskinstance.py:873: SAWarning: TypeDecorator ExecutorConfigType() will not produce a cache key because the ``cache_ok`` attribute is not set to True.  This can have significant performance implications including some performance degradations in comparison to prior SQLAlchemy versions.  Set this attribute to True if this type object's state is safe to use in a cache key, or False to disable this warning. (Background on this error at: https://sqlalche.me/e/14/cprf)
  ti = qry.one_or_none()

[2023-05-17T09:01:06.886+0000] {taskinstance.py:1406} INFO - Immediate failure requested. Marking task as FAILED. dag_id=job_1_tranvietcuong_2, task_id=file_sensor, execution_date=20230511T175000, start_date=20230517T090105, end_date=20230517T090106
[2023-05-17T09:01:06.938+0000] {warnings.py:110} WARNING - /usr/local/lib/python3.7/site-packages/***/utils/email.py:120: RemovedInAirflow3Warning: Fetching SMTP credentials from configuration variables will be deprecated in a future release. Please set credentials using a connection instead.
  send_mime_email(e_from=mail_from, e_to=recipients, mime_msg=msg, conn_id=conn_id, dryrun=dryrun)

[2023-05-17T09:01:06.939+0000] {configuration.py:569} WARNING - section/key [smtp/smtp_user] not found in config
[2023-05-17T09:01:06.940+0000] {email.py:229} INFO - Email alerting: attempt 1
[2023-05-17T09:01:06.968+0000] {configuration.py:569} WARNING - section/key [smtp/smtp_user] not found in config
[2023-05-17T09:01:06.969+0000] {email.py:229} INFO - Email alerting: attempt 1
[2023-05-17T09:01:06.971+0000] {taskinstance.py:1914} ERROR - Failed to send email to: ['user@example.com']
Traceback (most recent call last):
  File "/usr/local/lib/python3.7/site-packages/airflow/models/taskinstance.py", line 1457, in _run_raw_task
    self._execute_task_with_callbacks(context, test_mode)
  File "/usr/local/lib/python3.7/site-packages/airflow/models/taskinstance.py", line 1603, in _execute_task_with_callbacks
    result = self._execute_task(context, task_orig)
  File "/usr/local/lib/python3.7/site-packages/airflow/models/taskinstance.py", line 1664, in _execute_task
    result = execute_callable(context=context)
  File "/usr/local/lib/python3.7/site-packages/airflow/sensors/base.py", line 200, in execute
    raise AirflowSensorTimeout(f"Snap. Time is OUT. DAG id: {log_dag_id}")
airflow.exceptions.AirflowSensorTimeout: Snap. Time is OUT. DAG id: job_1_tranvietcuong_2

During handling of the above exception, another exception occurred:

Traceback (most recent call last):
  File "/usr/local/lib/python3.7/site-packages/airflow/models/taskinstance.py", line 2311, in email_alert
    send_email(task.email, subject, html_content)
  File "/usr/local/lib/python3.7/site-packages/airflow/utils/email.py", line 72, in send_email
    **kwargs,
  File "/usr/local/lib/python3.7/site-packages/airflow/utils/email.py", line 120, in send_email_smtp
    send_mime_email(e_from=mail_from, e_to=recipients, mime_msg=msg, conn_id=conn_id, dryrun=dryrun)
  File "/usr/local/lib/python3.7/site-packages/airflow/utils/email.py", line 231, in send_mime_email
    smtp_conn = _get_smtp_connection(smtp_host, smtp_port, smtp_timeout, smtp_ssl)
  File "/usr/local/lib/python3.7/site-packages/airflow/utils/email.py", line 265, in _get_smtp_connection
    else smtplib.SMTP(host=host, port=port, timeout=timeout)
  File "/usr/local/lib/python3.7/smtplib.py", line 251, in __init__
    (code, msg) = self.connect(host, port)
  File "/usr/local/lib/python3.7/smtplib.py", line 336, in connect
    self.sock = self._get_socket(host, port, self.timeout)
  File "/usr/local/lib/python3.7/smtplib.py", line 307, in _get_socket
    self.source_address)
  File "/usr/local/lib/python3.7/socket.py", line 728, in create_connection
    raise err
  File "/usr/local/lib/python3.7/socket.py", line 716, in create_connection
    sock.connect(sa)
OSError: [Errno 99] Cannot assign requested address

During handling of the above exception, another exception occurred:

Traceback (most recent call last):
  File "/usr/local/lib/python3.7/site-packages/airflow/models/taskinstance.py", line 1912, in handle_failure
    self.email_alert(error, task)
  File "/usr/local/lib/python3.7/site-packages/airflow/models/taskinstance.py", line 2313, in email_alert
    send_email(task.email, subject, html_content_err)
  File "/usr/local/lib/python3.7/site-packages/airflow/utils/email.py", line 72, in send_email
    **kwargs,
  File "/usr/local/lib/python3.7/site-packages/airflow/utils/email.py", line 120, in send_email_smtp
    send_mime_email(e_from=mail_from, e_to=recipients, mime_msg=msg, conn_id=conn_id, dryrun=dryrun)
  File "/usr/local/lib/python3.7/site-packages/airflow/utils/email.py", line 231, in send_mime_email
    smtp_conn = _get_smtp_connection(smtp_host, smtp_port, smtp_timeout, smtp_ssl)
  File "/usr/local/lib/python3.7/site-packages/airflow/utils/email.py", line 265, in _get_smtp_connection
    else smtplib.SMTP(host=host, port=port, timeout=timeout)
  File "/usr/local/lib/python3.7/smtplib.py", line 251, in __init__
    (code, msg) = self.connect(host, port)
  File "/usr/local/lib/python3.7/smtplib.py", line 336, in connect
    self.sock = self._get_socket(host, port, self.timeout)
  File "/usr/local/lib/python3.7/smtplib.py", line 307, in _get_socket
    self.source_address)
  File "/usr/local/lib/python3.7/socket.py", line 728, in create_connection
    raise err
  File "/usr/local/lib/python3.7/socket.py", line 716, in create_connection
    sock.connect(sa)
OSError: [Errno 99] Cannot assign requested address
[2023-05-17T09:01:06.977+0000] {taskinstance.py:1619} ERROR - Error when executing on_failure callback
Traceback (most recent call last):
  File "/usr/local/lib/python3.7/site-packages/airflow/models/taskinstance.py", line 1457, in _run_raw_task
    self._execute_task_with_callbacks(context, test_mode)
  File "/usr/local/lib/python3.7/site-packages/airflow/models/taskinstance.py", line 1603, in _execute_task_with_callbacks
    result = self._execute_task(context, task_orig)
  File "/usr/local/lib/python3.7/site-packages/airflow/models/taskinstance.py", line 1664, in _execute_task
    result = execute_callable(context=context)
  File "/usr/local/lib/python3.7/site-packages/airflow/sensors/base.py", line 200, in execute
    raise AirflowSensorTimeout(f"Snap. Time is OUT. DAG id: {log_dag_id}")
airflow.exceptions.AirflowSensorTimeout: Snap. Time is OUT. DAG id: job_1_tranvietcuong_2

During handling of the above exception, another exception occurred:

Traceback (most recent call last):
  File "/usr/local/lib/python3.7/site-packages/airflow/models/taskinstance.py", line 1617, in _run_finished_callback
    callback(context)
TypeError: send_file_not_found_email() takes 0 positional arguments but 1 was given
[2023-05-17T09:01:07.035+0000] {standard_task_runner.py:107} ERROR - Failed to execute job 3917 for task file_sensor (Snap. Time is OUT. DAG id: job_1_tranvietcuong_2; 288)
[2023-05-17T09:01:07.070+0000] {local_task_job.py:164} INFO - Task exited with return code 1
[2023-05-17T09:01:07.262+0000] {local_task_job.py:273} INFO - 0 downstream tasks scheduled from follow-on schedule check
