[2023-05-11T17:48:05.873+0000] {warnings.py:110} WARNING - /usr/local/lib/python3.7/site-packages/***/models/taskinstance.py:871: SAWarning: TypeDecorator ExecutorConfigType() will not produce a cache key because the ``cache_ok`` attribute is not set to True.  This can have significant performance implications including some performance degradations in comparison to prior SQLAlchemy versions.  Set this attribute to True if this type object's state is safe to use in a cache key, or False to disable this warning. (Background on this error at: https://sqlalche.me/e/14/cprf)
  ti: TaskInstance | None = qry.with_for_update().one_or_none()

[2023-05-11T17:48:05.947+0000] {taskinstance.py:1165} INFO - Dependencies all met for <TaskInstance: job_1_tranvietcuong.file_process manual__2023-05-11T17:46:58.769489+00:00 [queued]>
[2023-05-11T17:48:05.999+0000] {taskinstance.py:1165} INFO - Dependencies all met for <TaskInstance: job_1_tranvietcuong.file_process manual__2023-05-11T17:46:58.769489+00:00 [queued]>
[2023-05-11T17:48:06.000+0000] {taskinstance.py:1362} INFO - 
--------------------------------------------------------------------------------
[2023-05-11T17:48:06.000+0000] {taskinstance.py:1363} INFO - Starting attempt 2 of 2
[2023-05-11T17:48:06.001+0000] {taskinstance.py:1364} INFO - 
--------------------------------------------------------------------------------
[2023-05-11T17:48:06.082+0000] {taskinstance.py:1383} INFO - Executing <Task(PythonOperator): file_process> on 2023-05-11 17:46:58.769489+00:00
[2023-05-11T17:48:06.098+0000] {standard_task_runner.py:54} INFO - Started process 494 to run task
[2023-05-11T17:48:06.111+0000] {standard_task_runner.py:82} INFO - Running: ['***', 'tasks', 'run', 'job_1_tranvietcuong', 'file_process', 'manual__2023-05-11T17:46:58.769489+00:00', '--job-id', '183', '--raw', '--subdir', 'DAGS_FOLDER/tranvietcuong.py', '--cfg-path', '/tmp/tmpuq26sxys']
[2023-05-11T17:48:06.114+0000] {standard_task_runner.py:83} INFO - Job 183: Subtask file_process
[2023-05-11T17:48:06.117+0000] {dagbag.py:525} INFO - Filling up the DagBag from /opt/***/dags/tranvietcuong.py
[2023-05-11T17:48:06.398+0000] {task_command.py:384} INFO - Running <TaskInstance: job_1_tranvietcuong.file_process manual__2023-05-11T17:46:58.769489+00:00 [running]> on host 09877495cfa0
[2023-05-11T17:48:06.412+0000] {warnings.py:110} WARNING - /usr/local/lib/python3.7/site-packages/***/models/taskinstance.py:873: SAWarning: TypeDecorator ExecutorConfigType() will not produce a cache key because the ``cache_ok`` attribute is not set to True.  This can have significant performance implications including some performance degradations in comparison to prior SQLAlchemy versions.  Set this attribute to True if this type object's state is safe to use in a cache key, or False to disable this warning. (Background on this error at: https://sqlalche.me/e/14/cprf)
  ti = qry.one_or_none()

[2023-05-11T17:48:06.767+0000] {taskinstance.py:1592} INFO - Exporting the following env vars:
AIRFLOW_CTX_DAG_OWNER=***
AIRFLOW_CTX_DAG_ID=job_1_tranvietcuong
AIRFLOW_CTX_TASK_ID=file_process
AIRFLOW_CTX_EXECUTION_DATE=2023-05-11T17:46:58.769489+00:00
AIRFLOW_CTX_TRY_NUMBER=2
AIRFLOW_CTX_DAG_RUN_ID=manual__2023-05-11T17:46:58.769489+00:00
[2023-05-11T17:48:06.770+0000] {taskinstance.py:1851} ERROR - Task failed with exception
Traceback (most recent call last):
  File "/usr/local/lib/python3.7/site-packages/airflow/operators/python.py", line 175, in execute
    return_value = self.execute_callable()
  File "/usr/local/lib/python3.7/site-packages/airflow/operators/python.py", line 193, in execute_callable
    return self.python_callable(*self.op_args, **self.op_kwargs)
  File "/opt/airflow/dags/tranvietcuong.py", line 20, in file_process
    with open(file_write, 'w') as f:
FileNotFoundError: [Errno 2] No such file or directory: '/opt/airflow/dags/tmp2/tranvietcuong_dejob.txt'
[2023-05-11T17:48:06.827+0000] {taskinstance.py:1406} INFO - Marking task as FAILED. dag_id=job_1_tranvietcuong, task_id=file_process, execution_date=20230511T174658, start_date=20230511T174805, end_date=20230511T174806
[2023-05-11T17:48:06.900+0000] {standard_task_runner.py:107} ERROR - Failed to execute job 183 for task file_process ([Errno 2] No such file or directory: '/opt/airflow/dags/tmp2/tranvietcuong_dejob.txt'; 494)
[2023-05-11T17:48:06.949+0000] {local_task_job.py:164} INFO - Task exited with return code 1
[2023-05-11T17:48:07.106+0000] {local_task_job.py:273} INFO - 0 downstream tasks scheduled from follow-on schedule check
