[2023-05-11T08:11:41.217+0000] {warnings.py:110} WARNING - /usr/local/lib/python3.7/site-packages/***/models/taskinstance.py:871: SAWarning: TypeDecorator ExecutorConfigType() will not produce a cache key because the ``cache_ok`` attribute is not set to True.  This can have significant performance implications including some performance degradations in comparison to prior SQLAlchemy versions.  Set this attribute to True if this type object's state is safe to use in a cache key, or False to disable this warning. (Background on this error at: https://sqlalche.me/e/14/cprf)
  ti: TaskInstance | None = qry.with_for_update().one_or_none()

[2023-05-11T08:11:41.265+0000] {taskinstance.py:1165} INFO - Dependencies all met for <TaskInstance: spark_process_data_13.spark_job_clean_data_by_ssh manual__2023-05-11T08:10:35.418182+00:00 [queued]>
[2023-05-11T08:11:41.314+0000] {taskinstance.py:1165} INFO - Dependencies all met for <TaskInstance: spark_process_data_13.spark_job_clean_data_by_ssh manual__2023-05-11T08:10:35.418182+00:00 [queued]>
[2023-05-11T08:11:41.315+0000] {taskinstance.py:1362} INFO - 
--------------------------------------------------------------------------------
[2023-05-11T08:11:41.315+0000] {taskinstance.py:1363} INFO - Starting attempt 2 of 2
[2023-05-11T08:11:41.316+0000] {taskinstance.py:1364} INFO - 
--------------------------------------------------------------------------------
[2023-05-11T08:11:41.368+0000] {taskinstance.py:1383} INFO - Executing <Task(SSHOperator): spark_job_clean_data_by_ssh> on 2023-05-11 08:10:35.418182+00:00
[2023-05-11T08:11:41.380+0000] {standard_task_runner.py:54} INFO - Started process 3133 to run task
[2023-05-11T08:11:41.389+0000] {standard_task_runner.py:82} INFO - Running: ['***', 'tasks', 'run', 'spark_process_data_13', 'spark_job_clean_data_by_ssh', 'manual__2023-05-11T08:10:35.418182+00:00', '--job-id', '73', '--raw', '--subdir', 'DAGS_FOLDER/spark_process_scheduler.py', '--cfg-path', '/tmp/tmp4dak886e']
[2023-05-11T08:11:41.391+0000] {standard_task_runner.py:83} INFO - Job 73: Subtask spark_job_clean_data_by_ssh
[2023-05-11T08:11:41.393+0000] {dagbag.py:525} INFO - Filling up the DagBag from /opt/***/dags/spark_process_scheduler.py
[2023-05-11T08:11:41.680+0000] {task_command.py:384} INFO - Running <TaskInstance: spark_process_data_13.spark_job_clean_data_by_ssh manual__2023-05-11T08:10:35.418182+00:00 [running]> on host 09877495cfa0
[2023-05-11T08:11:41.689+0000] {warnings.py:110} WARNING - /usr/local/lib/python3.7/site-packages/***/models/taskinstance.py:873: SAWarning: TypeDecorator ExecutorConfigType() will not produce a cache key because the ``cache_ok`` attribute is not set to True.  This can have significant performance implications including some performance degradations in comparison to prior SQLAlchemy versions.  Set this attribute to True if this type object's state is safe to use in a cache key, or False to disable this warning. (Background on this error at: https://sqlalche.me/e/14/cprf)
  ti = qry.one_or_none()

[2023-05-11T08:11:41.919+0000] {taskinstance.py:1592} INFO - Exporting the following env vars:
AIRFLOW_CTX_DAG_EMAIL=pioneer22022001@gmail.com
AIRFLOW_CTX_DAG_OWNER=***
AIRFLOW_CTX_DAG_ID=spark_process_data_13
AIRFLOW_CTX_TASK_ID=spark_job_clean_data_by_ssh
AIRFLOW_CTX_EXECUTION_DATE=2023-05-11T08:10:35.418182+00:00
AIRFLOW_CTX_TRY_NUMBER=2
AIRFLOW_CTX_DAG_RUN_ID=manual__2023-05-11T08:10:35.418182+00:00
[2023-05-11T08:11:41.921+0000] {ssh.py:135} INFO - Creating ssh_client
[2023-05-11T08:11:42.036+0000] {ssh.py:112} INFO - ssh_hook is not provided or invalid. Trying ssh_conn_id to create SSHHook.
[2023-05-11T08:11:42.072+0000] {base.py:71} INFO - Using connection ID 'ssh_connection_spark' for task execution.
[2023-05-11T08:11:42.074+0000] {ssh.py:299} WARNING - No Host Key Verification. This won't protect against Man-In-The-Middle attacks
[2023-05-11T08:11:42.105+0000] {transport.py:1873} INFO - Connected (version 2.0, client OpenSSH_7.9p1)
[2023-05-11T08:11:42.221+0000] {transport.py:1873} INFO - Authentication (password) successful!
[2023-05-11T08:11:42.222+0000] {ssh.py:476} INFO - Running command: spark-submit --master spark://spark-master:7077 --conf spark.master=spark://spark-master:7077 --name spark_clean_data --verbose /opt/spark/app/preprocess_data.py
[2023-05-11T08:11:42.294+0000] {ssh.py:527} WARNING - bash: spark-submit: command not found
[2023-05-11T08:11:42.377+0000] {taskinstance.py:1851} ERROR - Task failed with exception
Traceback (most recent call last):
  File "/usr/local/lib/python3.7/site-packages/airflow/providers/ssh/operators/ssh.py", line 173, in execute
    result = self.run_ssh_client_command(ssh_client, self.command, context=context)
  File "/usr/local/lib/python3.7/site-packages/airflow/providers/ssh/operators/ssh.py", line 161, in run_ssh_client_command
    self.raise_for_status(exit_status, agg_stderr, context=context)
  File "/usr/local/lib/python3.7/site-packages/airflow/providers/ssh/operators/ssh.py", line 154, in raise_for_status
    raise AirflowException(f"SSH operator error: exit status = {exit_status}")
airflow.exceptions.AirflowException: SSH operator error: exit status = 127
[2023-05-11T08:11:42.396+0000] {taskinstance.py:1406} INFO - Marking task as FAILED. dag_id=spark_process_data_13, task_id=spark_job_clean_data_by_ssh, execution_date=20230511T081035, start_date=20230511T081141, end_date=20230511T081142
[2023-05-11T08:11:42.438+0000] {warnings.py:110} WARNING - /usr/local/lib/python3.7/site-packages/***/utils/email.py:120: RemovedInAirflow3Warning: Fetching SMTP credentials from configuration variables will be deprecated in a future release. Please set credentials using a connection instead.
  send_mime_email(e_from=mail_from, e_to=recipients, mime_msg=msg, conn_id=conn_id, dryrun=dryrun)

[2023-05-11T08:11:42.439+0000] {configuration.py:569} WARNING - section/key [smtp/smtp_user] not found in config
[2023-05-11T08:11:42.440+0000] {email.py:229} INFO - Email alerting: attempt 1
[2023-05-11T08:11:42.468+0000] {configuration.py:569} WARNING - section/key [smtp/smtp_user] not found in config
[2023-05-11T08:11:42.468+0000] {email.py:229} INFO - Email alerting: attempt 1
[2023-05-11T08:11:42.470+0000] {taskinstance.py:1914} ERROR - Failed to send email to: ['pioneer22022001@gmail.com']
Traceback (most recent call last):
  File "/usr/local/lib/python3.7/site-packages/airflow/models/taskinstance.py", line 1457, in _run_raw_task
    self._execute_task_with_callbacks(context, test_mode)
  File "/usr/local/lib/python3.7/site-packages/airflow/models/taskinstance.py", line 1603, in _execute_task_with_callbacks
    result = self._execute_task(context, task_orig)
  File "/usr/local/lib/python3.7/site-packages/airflow/models/taskinstance.py", line 1664, in _execute_task
    result = execute_callable(context=context)
  File "/usr/local/lib/python3.7/site-packages/airflow/providers/ssh/operators/ssh.py", line 173, in execute
    result = self.run_ssh_client_command(ssh_client, self.command, context=context)
  File "/usr/local/lib/python3.7/site-packages/airflow/providers/ssh/operators/ssh.py", line 161, in run_ssh_client_command
    self.raise_for_status(exit_status, agg_stderr, context=context)
  File "/usr/local/lib/python3.7/site-packages/airflow/providers/ssh/operators/ssh.py", line 154, in raise_for_status
    raise AirflowException(f"SSH operator error: exit status = {exit_status}")
airflow.exceptions.AirflowException: SSH operator error: exit status = 127

During handling of the above exception, another exception occurred:

Traceback (most recent call last):
  File "/usr/local/lib/python3.7/site-packages/airflow/models/taskinstance.py", line 2311, in email_alert
    send_email(task.email, subject, html_content)
  File "/usr/local/lib/python3.7/site-packages/airflow/utils/email.py", line 72, in send_email
    **kwargs,
  File "/usr/local/lib/python3.7/site-packages/airflow/utils/email.py", line 120, in send_email_smtp
    send_mime_email(e_from=mail_from, e_to=recipients, mime_msg=msg, conn_id=conn_id, dryrun=dryrun)
  File "/usr/local/lib/python3.7/site-packages/airflow/utils/email.py", line 231, in send_mime_email
    smtp_conn = _get_smtp_connection(smtp_host, smtp_port, smtp_timeout, smtp_ssl)
  File "/usr/local/lib/python3.7/site-packages/airflow/utils/email.py", line 265, in _get_smtp_connection
    else smtplib.SMTP(host=host, port=port, timeout=timeout)
  File "/usr/local/lib/python3.7/smtplib.py", line 251, in __init__
    (code, msg) = self.connect(host, port)
  File "/usr/local/lib/python3.7/smtplib.py", line 336, in connect
    self.sock = self._get_socket(host, port, self.timeout)
  File "/usr/local/lib/python3.7/smtplib.py", line 307, in _get_socket
    self.source_address)
  File "/usr/local/lib/python3.7/socket.py", line 728, in create_connection
    raise err
  File "/usr/local/lib/python3.7/socket.py", line 716, in create_connection
    sock.connect(sa)
OSError: [Errno 99] Cannot assign requested address

During handling of the above exception, another exception occurred:

Traceback (most recent call last):
  File "/usr/local/lib/python3.7/site-packages/airflow/models/taskinstance.py", line 1912, in handle_failure
    self.email_alert(error, task)
  File "/usr/local/lib/python3.7/site-packages/airflow/models/taskinstance.py", line 2313, in email_alert
    send_email(task.email, subject, html_content_err)
  File "/usr/local/lib/python3.7/site-packages/airflow/utils/email.py", line 72, in send_email
    **kwargs,
  File "/usr/local/lib/python3.7/site-packages/airflow/utils/email.py", line 120, in send_email_smtp
    send_mime_email(e_from=mail_from, e_to=recipients, mime_msg=msg, conn_id=conn_id, dryrun=dryrun)
  File "/usr/local/lib/python3.7/site-packages/airflow/utils/email.py", line 231, in send_mime_email
    smtp_conn = _get_smtp_connection(smtp_host, smtp_port, smtp_timeout, smtp_ssl)
  File "/usr/local/lib/python3.7/site-packages/airflow/utils/email.py", line 265, in _get_smtp_connection
    else smtplib.SMTP(host=host, port=port, timeout=timeout)
  File "/usr/local/lib/python3.7/smtplib.py", line 251, in __init__
    (code, msg) = self.connect(host, port)
  File "/usr/local/lib/python3.7/smtplib.py", line 336, in connect
    self.sock = self._get_socket(host, port, self.timeout)
  File "/usr/local/lib/python3.7/smtplib.py", line 307, in _get_socket
    self.source_address)
  File "/usr/local/lib/python3.7/socket.py", line 728, in create_connection
    raise err
  File "/usr/local/lib/python3.7/socket.py", line 716, in create_connection
    sock.connect(sa)
OSError: [Errno 99] Cannot assign requested address
[2023-05-11T08:11:42.524+0000] {standard_task_runner.py:107} ERROR - Failed to execute job 73 for task spark_job_clean_data_by_ssh (SSH operator error: exit status = 127; 3133)
[2023-05-11T08:11:42.563+0000] {local_task_job.py:164} INFO - Task exited with return code 1
[2023-05-11T08:11:42.697+0000] {local_task_job.py:273} INFO - 0 downstream tasks scheduled from follow-on schedule check
