[2023-05-12T03:51:12.753+0000] {warnings.py:110} WARNING - /usr/local/lib/python3.7/site-packages/***/models/taskinstance.py:871: SAWarning: TypeDecorator ExecutorConfigType() will not produce a cache key because the ``cache_ok`` attribute is not set to True.  This can have significant performance implications including some performance degradations in comparison to prior SQLAlchemy versions.  Set this attribute to True if this type object's state is safe to use in a cache key, or False to disable this warning. (Background on this error at: https://sqlalche.me/e/14/cprf)
  ti: TaskInstance | None = qry.with_for_update().one_or_none()

[2023-05-12T03:51:12.825+0000] {taskinstance.py:1165} INFO - Dependencies all met for <TaskInstance: job_1_tranvietcuong.file_sensor scheduled__2023-05-11T20:50:00+00:00 [queued]>
[2023-05-12T03:51:12.877+0000] {taskinstance.py:1165} INFO - Dependencies all met for <TaskInstance: job_1_tranvietcuong.file_sensor scheduled__2023-05-11T20:50:00+00:00 [queued]>
[2023-05-12T03:51:12.877+0000] {taskinstance.py:1362} INFO - 
--------------------------------------------------------------------------------
[2023-05-12T03:51:12.878+0000] {taskinstance.py:1363} INFO - Starting attempt 1 of 1
[2023-05-12T03:51:12.878+0000] {taskinstance.py:1364} INFO - 
--------------------------------------------------------------------------------
[2023-05-12T03:51:12.957+0000] {taskinstance.py:1383} INFO - Executing <Task(FileSensor): file_sensor> on 2023-05-11 20:50:00+00:00
[2023-05-12T03:51:12.972+0000] {standard_task_runner.py:54} INFO - Started process 231 to run task
[2023-05-12T03:51:12.982+0000] {standard_task_runner.py:82} INFO - Running: ['***', 'tasks', 'run', 'job_1_tranvietcuong', 'file_sensor', 'scheduled__2023-05-11T20:50:00+00:00', '--job-id', '282', '--raw', '--subdir', 'DAGS_FOLDER/tranvietcuong.py', '--cfg-path', '/tmp/tmpppzifgsp']
[2023-05-12T03:51:12.984+0000] {standard_task_runner.py:83} INFO - Job 282: Subtask file_sensor
[2023-05-12T03:51:12.987+0000] {dagbag.py:525} INFO - Filling up the DagBag from /opt/***/dags/tranvietcuong.py
[2023-05-12T03:51:13.247+0000] {task_command.py:384} INFO - Running <TaskInstance: job_1_tranvietcuong.file_sensor scheduled__2023-05-11T20:50:00+00:00 [running]> on host 09877495cfa0
[2023-05-12T03:51:13.261+0000] {warnings.py:110} WARNING - /usr/local/lib/python3.7/site-packages/***/models/taskinstance.py:873: SAWarning: TypeDecorator ExecutorConfigType() will not produce a cache key because the ``cache_ok`` attribute is not set to True.  This can have significant performance implications including some performance degradations in comparison to prior SQLAlchemy versions.  Set this attribute to True if this type object's state is safe to use in a cache key, or False to disable this warning. (Background on this error at: https://sqlalche.me/e/14/cprf)
  ti = qry.one_or_none()

[2023-05-12T03:51:13.552+0000] {taskinstance.py:1592} INFO - Exporting the following env vars:
AIRFLOW_CTX_DAG_EMAIL=user@example.com
AIRFLOW_CTX_DAG_OWNER=***
AIRFLOW_CTX_DAG_ID=job_1_tranvietcuong
AIRFLOW_CTX_TASK_ID=file_sensor
AIRFLOW_CTX_EXECUTION_DATE=2023-05-11T20:50:00+00:00
AIRFLOW_CTX_TRY_NUMBER=1
AIRFLOW_CTX_DAG_RUN_ID=scheduled__2023-05-11T20:50:00+00:00
[2023-05-12T03:51:13.612+0000] {base.py:71} INFO - Using connection ID 'fs_default' for task execution.
[2023-05-12T03:51:13.614+0000] {filesystem.py:58} INFO - Poking for file /opt/***/dags/tmp/*dejob*
[2023-05-12T03:51:13.631+0000] {warnings.py:110} WARNING - /usr/local/lib/python3.7/site-packages/***/models/taskinstance.py:873: SAWarning: TypeDecorator ExecutorConfigType() will not produce a cache key because the ``cache_ok`` attribute is not set to True.  This can have significant performance implications including some performance degradations in comparison to prior SQLAlchemy versions.  Set this attribute to True if this type object's state is safe to use in a cache key, or False to disable this warning. (Background on this error at: https://sqlalche.me/e/14/cprf)
  ti = qry.one_or_none()

[2023-05-12T03:51:13.691+0000] {taskinstance.py:1815} INFO - Rescheduling task, marking task as UP_FOR_RESCHEDULE
[2023-05-12T03:51:13.727+0000] {local_task_job.py:164} INFO - Task exited with return code 0
[2023-05-12T03:51:13.838+0000] {local_task_job.py:273} INFO - 0 downstream tasks scheduled from follow-on schedule check
[2023-05-12T03:51:25.378+0000] {warnings.py:110} WARNING - /usr/local/lib/python3.7/site-packages/***/models/taskinstance.py:871: SAWarning: TypeDecorator ExecutorConfigType() will not produce a cache key because the ``cache_ok`` attribute is not set to True.  This can have significant performance implications including some performance degradations in comparison to prior SQLAlchemy versions.  Set this attribute to True if this type object's state is safe to use in a cache key, or False to disable this warning. (Background on this error at: https://sqlalche.me/e/14/cprf)
  ti: TaskInstance | None = qry.with_for_update().one_or_none()

[2023-05-12T03:51:25.448+0000] {taskinstance.py:1165} INFO - Dependencies all met for <TaskInstance: job_1_tranvietcuong.file_sensor scheduled__2023-05-11T20:50:00+00:00 [queued]>
[2023-05-12T03:51:25.501+0000] {taskinstance.py:1165} INFO - Dependencies all met for <TaskInstance: job_1_tranvietcuong.file_sensor scheduled__2023-05-11T20:50:00+00:00 [queued]>
[2023-05-12T03:51:25.502+0000] {taskinstance.py:1362} INFO - 
--------------------------------------------------------------------------------
[2023-05-12T03:51:25.502+0000] {taskinstance.py:1363} INFO - Starting attempt 1 of 1
[2023-05-12T03:51:25.503+0000] {taskinstance.py:1364} INFO - 
--------------------------------------------------------------------------------
[2023-05-12T03:51:25.590+0000] {taskinstance.py:1383} INFO - Executing <Task(FileSensor): file_sensor> on 2023-05-11 20:50:00+00:00
[2023-05-12T03:51:25.607+0000] {standard_task_runner.py:54} INFO - Started process 259 to run task
[2023-05-12T03:51:25.619+0000] {standard_task_runner.py:82} INFO - Running: ['***', 'tasks', 'run', 'job_1_tranvietcuong', 'file_sensor', 'scheduled__2023-05-11T20:50:00+00:00', '--job-id', '291', '--raw', '--subdir', 'DAGS_FOLDER/tranvietcuong.py', '--cfg-path', '/tmp/tmpmq0ezwas']
[2023-05-12T03:51:25.621+0000] {standard_task_runner.py:83} INFO - Job 291: Subtask file_sensor
[2023-05-12T03:51:25.623+0000] {dagbag.py:525} INFO - Filling up the DagBag from /opt/***/dags/tranvietcuong.py
[2023-05-12T03:51:25.926+0000] {task_command.py:384} INFO - Running <TaskInstance: job_1_tranvietcuong.file_sensor scheduled__2023-05-11T20:50:00+00:00 [running]> on host 09877495cfa0
[2023-05-12T03:51:25.936+0000] {warnings.py:110} WARNING - /usr/local/lib/python3.7/site-packages/***/models/taskinstance.py:873: SAWarning: TypeDecorator ExecutorConfigType() will not produce a cache key because the ``cache_ok`` attribute is not set to True.  This can have significant performance implications including some performance degradations in comparison to prior SQLAlchemy versions.  Set this attribute to True if this type object's state is safe to use in a cache key, or False to disable this warning. (Background on this error at: https://sqlalche.me/e/14/cprf)
  ti = qry.one_or_none()

[2023-05-12T03:51:26.297+0000] {taskinstance.py:1592} INFO - Exporting the following env vars:
AIRFLOW_CTX_DAG_EMAIL=user@example.com
AIRFLOW_CTX_DAG_OWNER=***
AIRFLOW_CTX_DAG_ID=job_1_tranvietcuong
AIRFLOW_CTX_TASK_ID=file_sensor
AIRFLOW_CTX_EXECUTION_DATE=2023-05-11T20:50:00+00:00
AIRFLOW_CTX_TRY_NUMBER=1
AIRFLOW_CTX_DAG_RUN_ID=scheduled__2023-05-11T20:50:00+00:00
[2023-05-12T03:51:26.388+0000] {base.py:71} INFO - Using connection ID 'fs_default' for task execution.
[2023-05-12T03:51:26.390+0000] {filesystem.py:58} INFO - Poking for file /opt/***/dags/tmp/*dejob*
[2023-05-12T03:51:26.424+0000] {warnings.py:110} WARNING - /usr/local/lib/python3.7/site-packages/***/models/taskinstance.py:873: SAWarning: TypeDecorator ExecutorConfigType() will not produce a cache key because the ``cache_ok`` attribute is not set to True.  This can have significant performance implications including some performance degradations in comparison to prior SQLAlchemy versions.  Set this attribute to True if this type object's state is safe to use in a cache key, or False to disable this warning. (Background on this error at: https://sqlalche.me/e/14/cprf)
  ti = qry.one_or_none()

[2023-05-12T03:51:26.564+0000] {taskinstance.py:1815} INFO - Rescheduling task, marking task as UP_FOR_RESCHEDULE
[2023-05-12T03:51:26.597+0000] {local_task_job.py:164} INFO - Task exited with return code 0
[2023-05-12T03:51:27.273+0000] {local_task_job.py:273} INFO - 0 downstream tasks scheduled from follow-on schedule check
[2023-05-12T03:51:39.231+0000] {warnings.py:110} WARNING - /usr/local/lib/python3.7/site-packages/***/models/taskinstance.py:871: SAWarning: TypeDecorator ExecutorConfigType() will not produce a cache key because the ``cache_ok`` attribute is not set to True.  This can have significant performance implications including some performance degradations in comparison to prior SQLAlchemy versions.  Set this attribute to True if this type object's state is safe to use in a cache key, or False to disable this warning. (Background on this error at: https://sqlalche.me/e/14/cprf)
  ti: TaskInstance | None = qry.with_for_update().one_or_none()

[2023-05-12T03:51:39.313+0000] {taskinstance.py:1165} INFO - Dependencies all met for <TaskInstance: job_1_tranvietcuong.file_sensor scheduled__2023-05-11T20:50:00+00:00 [queued]>
[2023-05-12T03:51:39.370+0000] {taskinstance.py:1165} INFO - Dependencies all met for <TaskInstance: job_1_tranvietcuong.file_sensor scheduled__2023-05-11T20:50:00+00:00 [queued]>
[2023-05-12T03:51:39.371+0000] {taskinstance.py:1362} INFO - 
--------------------------------------------------------------------------------
[2023-05-12T03:51:39.372+0000] {taskinstance.py:1363} INFO - Starting attempt 1 of 1
[2023-05-12T03:51:39.372+0000] {taskinstance.py:1364} INFO - 
--------------------------------------------------------------------------------
[2023-05-12T03:51:39.470+0000] {taskinstance.py:1383} INFO - Executing <Task(FileSensor): file_sensor> on 2023-05-11 20:50:00+00:00
[2023-05-12T03:51:39.486+0000] {standard_task_runner.py:54} INFO - Started process 297 to run task
[2023-05-12T03:51:39.510+0000] {standard_task_runner.py:82} INFO - Running: ['***', 'tasks', 'run', 'job_1_tranvietcuong', 'file_sensor', 'scheduled__2023-05-11T20:50:00+00:00', '--job-id', '305', '--raw', '--subdir', 'DAGS_FOLDER/tranvietcuong.py', '--cfg-path', '/tmp/tmpka1_hhiy']
[2023-05-12T03:51:39.512+0000] {standard_task_runner.py:83} INFO - Job 305: Subtask file_sensor
[2023-05-12T03:51:39.517+0000] {dagbag.py:525} INFO - Filling up the DagBag from /opt/***/dags/tranvietcuong.py
[2023-05-12T03:51:40.097+0000] {task_command.py:384} INFO - Running <TaskInstance: job_1_tranvietcuong.file_sensor scheduled__2023-05-11T20:50:00+00:00 [running]> on host 09877495cfa0
[2023-05-12T03:51:40.115+0000] {warnings.py:110} WARNING - /usr/local/lib/python3.7/site-packages/***/models/taskinstance.py:873: SAWarning: TypeDecorator ExecutorConfigType() will not produce a cache key because the ``cache_ok`` attribute is not set to True.  This can have significant performance implications including some performance degradations in comparison to prior SQLAlchemy versions.  Set this attribute to True if this type object's state is safe to use in a cache key, or False to disable this warning. (Background on this error at: https://sqlalche.me/e/14/cprf)
  ti = qry.one_or_none()

[2023-05-12T03:51:41.058+0000] {taskinstance.py:1592} INFO - Exporting the following env vars:
AIRFLOW_CTX_DAG_EMAIL=user@example.com
AIRFLOW_CTX_DAG_OWNER=***
AIRFLOW_CTX_DAG_ID=job_1_tranvietcuong
AIRFLOW_CTX_TASK_ID=file_sensor
AIRFLOW_CTX_EXECUTION_DATE=2023-05-11T20:50:00+00:00
AIRFLOW_CTX_TRY_NUMBER=1
AIRFLOW_CTX_DAG_RUN_ID=scheduled__2023-05-11T20:50:00+00:00
[2023-05-12T03:51:42.053+0000] {connection.py:429} ERROR - Unable to retrieve connection from secrets backend (MetastoreBackend). Checking subsequent secrets backend.
Traceback (most recent call last):
  File "/usr/local/lib/python3.7/site-packages/sqlalchemy/engine/base.py", line 1901, in _execute_context
    cursor, statement, parameters, context
  File "/usr/local/lib/python3.7/site-packages/sqlalchemy/engine/default.py", line 736, in do_execute
    cursor.execute(statement, parameters)
psycopg2.OperationalError: server closed the connection unexpectedly
	This probably means the server terminated abnormally
	before or while processing the request.


The above exception was the direct cause of the following exception:

Traceback (most recent call last):
  File "/usr/local/lib/python3.7/site-packages/airflow/models/connection.py", line 422, in get_connection_from_secrets
    conn = secrets_backend.get_connection(conn_id=conn_id)
  File "/usr/local/lib/python3.7/site-packages/airflow/utils/session.py", line 75, in wrapper
    return func(*args, session=session, **kwargs)
  File "/usr/local/lib/python3.7/site-packages/airflow/secrets/metastore.py", line 39, in get_connection
    conn = session.query(Connection).filter(Connection.conn_id == conn_id).first()
  File "/usr/local/lib/python3.7/site-packages/sqlalchemy/orm/query.py", line 2824, in first
    return self.limit(1)._iter().first()
  File "/usr/local/lib/python3.7/site-packages/sqlalchemy/orm/query.py", line 2919, in _iter
    execution_options={"_sa_orm_load_options": self.load_options},
  File "/usr/local/lib/python3.7/site-packages/sqlalchemy/orm/session.py", line 1714, in execute
    result = conn._execute_20(statement, params or {}, execution_options)
  File "/usr/local/lib/python3.7/site-packages/sqlalchemy/engine/base.py", line 1705, in _execute_20
    return meth(self, args_10style, kwargs_10style, execution_options)
  File "/usr/local/lib/python3.7/site-packages/sqlalchemy/sql/elements.py", line 335, in _execute_on_connection
    self, multiparams, params, execution_options
  File "/usr/local/lib/python3.7/site-packages/sqlalchemy/engine/base.py", line 1582, in _execute_clauseelement
    cache_hit=cache_hit,
  File "/usr/local/lib/python3.7/site-packages/sqlalchemy/engine/base.py", line 1944, in _execute_context
    e, statement, parameters, cursor, context
  File "/usr/local/lib/python3.7/site-packages/sqlalchemy/engine/base.py", line 2125, in _handle_dbapi_exception
    sqlalchemy_exception, with_traceback=exc_info[2], from_=e
  File "/usr/local/lib/python3.7/site-packages/sqlalchemy/util/compat.py", line 211, in raise_
    raise exception
  File "/usr/local/lib/python3.7/site-packages/sqlalchemy/engine/base.py", line 1901, in _execute_context
    cursor, statement, parameters, context
  File "/usr/local/lib/python3.7/site-packages/sqlalchemy/engine/default.py", line 736, in do_execute
    cursor.execute(statement, parameters)
sqlalchemy.exc.OperationalError: (psycopg2.OperationalError) server closed the connection unexpectedly
	This probably means the server terminated abnormally
	before or while processing the request.

[SQL: SELECT connection.password AS connection_password, connection.extra AS connection_extra, connection.id AS connection_id, connection.conn_id AS connection_conn_id, connection.conn_type AS connection_conn_type, connection.description AS connection_description, connection.host AS connection_host, connection.schema AS connection_schema, connection.login AS connection_login, connection.port AS connection_port, connection.is_encrypted AS connection_is_encrypted, connection.is_extra_encrypted AS connection_is_extra_encrypted 
FROM connection 
WHERE connection.conn_id = %(conn_id_1)s 
 LIMIT %(param_1)s]
[parameters: {'conn_id_1': 'fs_default', 'param_1': 1}]
(Background on this error at: https://sqlalche.me/e/14/e3q8)
[2023-05-12T03:51:43.835+0000] {standard_task_runner.py:107} ERROR - Failed to execute job 305 for task file_sensor ((psycopg2.OperationalError) could not translate host name "postgres" to address: Temporary failure in name resolution

(Background on this error at: https://sqlalche.me/e/14/e3q8); 297)
[2023-05-12T03:51:43.902+0000] {local_task_job.py:164} INFO - Task exited with return code 1
[2023-05-12T03:51:43.928+0000] {local_task_job.py:281} INFO - Skipping mini scheduling run due to exception: None
Traceback (most recent call last):
  File "/usr/local/lib/python3.7/site-packages/sqlalchemy/engine/base.py", line 3361, in _wrap_pool_connect
    return fn()
  File "/usr/local/lib/python3.7/site-packages/sqlalchemy/pool/base.py", line 327, in connect
    return _ConnectionFairy._checkout(self)
  File "/usr/local/lib/python3.7/site-packages/sqlalchemy/pool/base.py", line 894, in _checkout
    fairy = _ConnectionRecord.checkout(pool)
  File "/usr/local/lib/python3.7/site-packages/sqlalchemy/pool/base.py", line 493, in checkout
    rec = pool._do_get()
  File "/usr/local/lib/python3.7/site-packages/sqlalchemy/pool/impl.py", line 256, in _do_get
    return self._create_connection()
  File "/usr/local/lib/python3.7/site-packages/sqlalchemy/pool/base.py", line 273, in _create_connection
    return _ConnectionRecord(self)
  File "/usr/local/lib/python3.7/site-packages/sqlalchemy/pool/base.py", line 388, in __init__
    self.__connect()
  File "/usr/local/lib/python3.7/site-packages/sqlalchemy/pool/base.py", line 691, in __connect
    pool.logger.debug("Error on connect(): %s", e)
  File "/usr/local/lib/python3.7/site-packages/sqlalchemy/util/langhelpers.py", line 72, in __exit__
    with_traceback=exc_tb,
  File "/usr/local/lib/python3.7/site-packages/sqlalchemy/util/compat.py", line 211, in raise_
    raise exception
  File "/usr/local/lib/python3.7/site-packages/sqlalchemy/pool/base.py", line 686, in __connect
    self.dbapi_connection = connection = pool._invoke_creator(self)
  File "/usr/local/lib/python3.7/site-packages/sqlalchemy/engine/create.py", line 574, in connect
    return dialect.connect(*cargs, **cparams)
  File "/usr/local/lib/python3.7/site-packages/sqlalchemy/engine/default.py", line 598, in connect
    return self.dbapi.connect(*cargs, **cparams)
  File "/usr/local/lib/python3.7/site-packages/psycopg2/__init__.py", line 122, in connect
    conn = _connect(dsn, connection_factory=connection_factory, **kwasync)
psycopg2.OperationalError: could not translate host name "postgres" to address: Temporary failure in name resolution


The above exception was the direct cause of the following exception:

Traceback (most recent call last):
  File "/usr/local/lib/python3.7/site-packages/airflow/jobs/local_task_job.py", line 243, in _run_mini_scheduler_on_child_tasks
    session=session,
  File "/usr/local/lib/python3.7/site-packages/sqlalchemy/orm/query.py", line 2870, in one
    return self._iter().one()
  File "/usr/local/lib/python3.7/site-packages/sqlalchemy/orm/query.py", line 2919, in _iter
    execution_options={"_sa_orm_load_options": self.load_options},
  File "/usr/local/lib/python3.7/site-packages/sqlalchemy/orm/session.py", line 1713, in execute
    conn = self._connection_for_bind(bind)
  File "/usr/local/lib/python3.7/site-packages/sqlalchemy/orm/session.py", line 1553, in _connection_for_bind
    engine, execution_options
  File "/usr/local/lib/python3.7/site-packages/sqlalchemy/orm/session.py", line 747, in _connection_for_bind
    conn = bind.connect()
  File "/usr/local/lib/python3.7/site-packages/sqlalchemy/engine/base.py", line 3315, in connect
    return self._connection_cls(self, close_with_result=close_with_result)
  File "/usr/local/lib/python3.7/site-packages/sqlalchemy/engine/base.py", line 96, in __init__
    else engine.raw_connection()
  File "/usr/local/lib/python3.7/site-packages/sqlalchemy/engine/base.py", line 3394, in raw_connection
    return self._wrap_pool_connect(self.pool.connect, _connection)
  File "/usr/local/lib/python3.7/site-packages/sqlalchemy/engine/base.py", line 3365, in _wrap_pool_connect
    e, dialect, self
  File "/usr/local/lib/python3.7/site-packages/sqlalchemy/engine/base.py", line 2199, in _handle_dbapi_exception_noconnection
    sqlalchemy_exception, with_traceback=exc_info[2], from_=e
  File "/usr/local/lib/python3.7/site-packages/sqlalchemy/util/compat.py", line 211, in raise_
    raise exception
  File "/usr/local/lib/python3.7/site-packages/sqlalchemy/engine/base.py", line 3361, in _wrap_pool_connect
    return fn()
  File "/usr/local/lib/python3.7/site-packages/sqlalchemy/pool/base.py", line 327, in connect
    return _ConnectionFairy._checkout(self)
  File "/usr/local/lib/python3.7/site-packages/sqlalchemy/pool/base.py", line 894, in _checkout
    fairy = _ConnectionRecord.checkout(pool)
  File "/usr/local/lib/python3.7/site-packages/sqlalchemy/pool/base.py", line 493, in checkout
    rec = pool._do_get()
  File "/usr/local/lib/python3.7/site-packages/sqlalchemy/pool/impl.py", line 256, in _do_get
    return self._create_connection()
  File "/usr/local/lib/python3.7/site-packages/sqlalchemy/pool/base.py", line 273, in _create_connection
    return _ConnectionRecord(self)
  File "/usr/local/lib/python3.7/site-packages/sqlalchemy/pool/base.py", line 388, in __init__
    self.__connect()
  File "/usr/local/lib/python3.7/site-packages/sqlalchemy/pool/base.py", line 691, in __connect
    pool.logger.debug("Error on connect(): %s", e)
  File "/usr/local/lib/python3.7/site-packages/sqlalchemy/util/langhelpers.py", line 72, in __exit__
    with_traceback=exc_tb,
  File "/usr/local/lib/python3.7/site-packages/sqlalchemy/util/compat.py", line 211, in raise_
    raise exception
  File "/usr/local/lib/python3.7/site-packages/sqlalchemy/pool/base.py", line 686, in __connect
    self.dbapi_connection = connection = pool._invoke_creator(self)
  File "/usr/local/lib/python3.7/site-packages/sqlalchemy/engine/create.py", line 574, in connect
    return dialect.connect(*cargs, **cparams)
  File "/usr/local/lib/python3.7/site-packages/sqlalchemy/engine/default.py", line 598, in connect
    return self.dbapi.connect(*cargs, **cparams)
  File "/usr/local/lib/python3.7/site-packages/psycopg2/__init__.py", line 122, in connect
    conn = _connect(dsn, connection_factory=connection_factory, **kwasync)
sqlalchemy.exc.OperationalError: (psycopg2.OperationalError) could not translate host name "postgres" to address: Temporary failure in name resolution

(Background on this error at: https://sqlalche.me/e/14/e3q8)
